Workbook
Name Aperturas: EJERCICIOS!$C$3:$C$5
Name Aperturas_Bajo: EJERCICIOS!$C$6:$C$6
Name Aperturas_Inclinado: EJERCICIOS!$C$3:$C$3
Name Aperturas_Medio: EJERCICIOS!$C$4:$C$5
Name Band_Pull_Apart: EJERCICIOS!$C$7:$C$7
Name BASES_AGARRE: EJERCICIOS!$I$3:$I$3
Name BASES_ANTEBRAZO: EJERCICIOS!$I$4:$I$4
Name BASES_BICEPS: EJERCICIOS!$I$5:$I$6
Name BASES_CIERRE: EJERCICIOS!$I$7:$I$10
Name BASES_CORE: EJERCICIOS!$I$11:$I$14
Name BASES_CUADRICEPS: EJERCICIOS!$I$15:$I$17
Name BASES_ESPALDA: EJERCICIOS!$I$18:$I$23
Name BASES_ESPALDA_ANCHURA: EJERCICIOS!$I$56:$I$58
Name BASES_ESPALDA_DENSIDAD: EJERCICIOS!$I$59:$I$61
Name BASES_FEMORAL: EJERCICIOS!$I$24:$I$25
Name BASES_GEMELO: EJERCICIOS!$I$26:$I$27
Name BASES_HOMBRO: EJERCICIOS!$I$28:$I$33
Name BASES_LIST: EJERCICIOS!$F$2:$F$42
Name BASES_LUMBAR: EJERCICIOS!$I$34:$I$35
Name BASES_PECHO: EJERCICIOS!$I$36:$I$42
Name BASES_PECHO_ALTO: EJERCICIOS!$I$51:$I$52
Name BASES_PECHO_AMPLITUD: EJERCICIOS!$I$50:$I$52
Name BASES_PECHO_BAJO: EJERCICIOS!$I$53:$I$55
Name BASES_PECHO_MEDIO: EJERCICIOS!$I$49:$I$50
Name BASES_PECHO_PLANO: EJERCICIOS!$I$47:$I$48
Name BASES_TRAPECIOS: EJERCICIOS!$I$43:$I$45
Name BASES_TRICEPS: EJERCICIOS!$I$46:$I$48
Name Crunch: EJERCICIOS!$C$8:$C$9
Name Curl_Biceps: EJERCICIOS!$C$10:$C$15
Name Curl_Femoral: EJERCICIOS!$C$16:$C$17
Name Curl_Martillo: EJERCICIOS!$C$18:$C$18
Name Curl_Muneca: EJERCICIOS!$C$19:$C$21
Name Curl_Rumano: EJERCICIOS!$C$22:$C$22
Name Dominadas: EJERCICIOS!$C$23:$C$23
Name Elevacion_Gemelo: EJERCICIOS!$C$24:$C$25
Name Elevacion_Piernas: EJERCICIOS!$C$26:$C$26
Name Elevacion_Talones: EJERCICIOS!$C$27:$C$27
Name Elevaciones_Laterales: EJERCICIOS!$C$28:$C$30
Name Elevaciones_Posteriores: EJERCICIOS!$C$31:$C$31
Name Encogimientos: EJERCICIOS!$C$32:$C$32
Name Estiramiento: EJERCICIOS!$C$33:$C$33
Name Extension_Cuadriceps: EJERCICIOS!$C$34:$C$35
Name Extension_Triceps: EJERCICIOS!$C$36:$C$39
Name Face_Pull: EJERCICIOS!$C$40:$C$41
Name Farmer_Carry: EJERCICIOS!$C$42:$C$42
Name Fondos: EJERCICIOS!$C$43:$C$43
Name Hip_Circle: EJERCICIOS!$C$44:$C$44
Name Hiperextension: EJERCICIOS!$C$45:$C$45
Name Jalon: EJERCICIOS!$C$47:$C$49
Name JM_Press: EJERCICIOS!$C$46:$C$46
Name Lagartija: EJERCICIOS!$C$50:$C$50
Name Pajaro: EJERCICIOS!$C$51:$C$51
Name Peck_Deck_Invertida: EJERCICIOS!$C$52:$C$52
Name Perro: EJERCICIOS!$C$53:$C$53
Name Peso_Muerto_Parcial: EJERCICIOS!$C$54:$C$54
Name Plancha: EJERCICIOS!$C$77:$C$77
Name Prensa_Pierna: EJERCICIOS!$C$55:$C$56
Name Press_Inclinado: EJERCICIOS!$C$61:$C$64
Name Press_Militar: EJERCICIOS!$C$65:$C$65
Name Press_Plano: EJERCICIOS!$C$57:$C$60

Sheet LUNES
A1: LUNES -- EMPUJE · Pecho + Hombro + Triceps + Cuadriceps
A2: Ejercicio Base | B2: Variante | C2: Tipo | D2: Series | E2: Peso C. | F2: SERIE 1 | I2: SERIE 2 | L2: SERIE 3 | O2: SERIE 4 | R2: SERIE 5 | U2: eRM | V2: Sugerencia
F3: Kg | G3: Reps | H3: RIR | I3: Kg | J3: Reps | K3: RIR | L3: Kg | M3: Reps | N3: RIR | O3: Kg | P3: Reps | Q3: RIR | R3: Kg | S3: Reps | T3: RIR
A4: -- CALENTAMIENTO --
A5: Estiramiento gemelo tumbado -- 30 seg cada lado -- antes de empezar
A6: Perro | B6: Postura Yoga | D6: 2 | V6: 60 seg -- movilidad toracica
A7: Lagartija | B7: Calentamiento | D7: 2 | V7: 60 seg -- apertura de caderas
A8: Hiperextension | B8: Banco Romano (calent.) | D8: 2 | V8: Mov. controlado -- sin carga
A10: SEMANA 1 HIP -- Hipertrofia
A11: — PECHO —
A12: · Medio
A13: Press Plano | B13: Mancuernas | C13: =IFERROR(INDEX(EJERCICIOS!$D$3:$D$75,MATCH(A13&"|"&B13,EJERCICIOS!$G$3:$G$75,0)),"--") -> mancuerna | D13: 3 | E13: =IFERROR(LOOKUP(2,1/(MEDIDAS_Y_PESO!$B$3:$B$3<>""),MEDIDAS_Y_PESO!$B$3:$B$3),"--") -> 80 | U13: =IFERROR(IF(IF(X13>0,X13,IF(Z13>0,Z13,IF(AB13>0,AB13,0)))=0,"--",ROUND(CHOOSE(IF(X13>0,X13,IF(Z13>0,Z13,IF(AB13>0,AB13,0))),IF(C13="peso_corporal",IF(ISNUMBER(E13),E13,0)+F13,F13)*(1+G13/30),IF(C13="peso_corporal",IF(ISNUMBER(E13),E13,0)+I13,I13)*(1+J13/30),IF(C13="peso_corporal",IF(ISNUMBER(E13),E13,0)+L13,L13)*(1+M13/30),IF(C13="peso_corporal",IF(ISNUMBER(E13),E13,0)+O13,O13)*(1+P13/30),IF(C13="peso_corporal",IF(ISNUMBER(E13),E13,0)+R13,R13)*(1+S13/30)),1)),"--") -> -- | V13: =IF(SUGERENCIAS!N4="SIN","Sin datos anteriores",IF(SUGERENCIAS!N4="SUBIR_F","^ SUBIR FUERTE | Kg:"&ROUND(SUGERENCIAS!K4,1)&" R:"&ROUND(SUGERENCIAS!L4,0)&" RIR:"&ROUND(SUGERENCIAS!M4,0),IF(SUGERENCIAS!N4="SUBIR_E","^ SUBIR (Est.) | Kg:"&ROUND(SUGERENCIAS!K4,1)&" R:"&ROUND(SUGERENCIAS!L4,0)&" RIR:"&ROUND(SUGERENCIAS!M4,0),IF(SUGERENCIAS!N4="SUBIR","^ SUBIR | Kg:"&ROUND(SUGERENCIAS!K4,1)&" R:"&ROUND(SUGERENCIAS!L4,0)&" RIR:"&ROUND(SUGERENCIAS!M4,0),IF(SUGERENCIAS!N4="BAJAR","v BAJAR | Kg:"&ROUND(SUGERENCIAS!K4,1)&" R:"&ROUND(SUGERENCIAS!L4,0)&" RIR:"&ROUND(SUGERENCIAS!M4,0),"= MANT | Kg:"&ROUND(SUGERENCIAS!K4,1)&" R:"&ROUND(SUGERENCIAS!L4,0)&" RIR:"&ROUND(SUGERENCIAS!M4,0)))))) -> Sin datos anteriores | W13: =MAX(IF((G13>0)*(IF(H13="",-1,H13)>=1)*(IF(H13="",-1,H13)<=3),IF(C13="peso_corporal",IF(ISNUMBER(E13),E13,0)+F13,F13)*G13*1000+F13,0),IF((J13>0)*(IF(K13="",-1,K13)>=1)*(IF(K13="",-1,K13)<=3),IF(C13="peso_corporal",IF(ISNUMBER(E13),E13,0)+I13,I13)*J13*1000+I13,0),IF((M13>0)*(IF(N13="",-1,N13)>=1)*(IF(N13="",-1,N13)<=3),IF(C13="peso_corporal",IF(ISNUMBER(E13),E13,0)+L13,L13)*M13*1000+L13,0),IF((P13>0)*(IF(Q13="",-1,Q13)>=1)*(IF(Q13="",-1,Q13)<=3),IF(C13="peso_corporal",IF(ISNUMBER(E13),E13,0)+O13,O13)*P13*1000+O13,0),IF((S13>0)*(IF(T13="",-1,T13)>=1)*(IF(T13="",-1,T13)<=3),IF(C13="peso_corporal",IF(ISNUMBER(E13),E13,0)+R13,R13)*S13*1000+R13,0)) -> 0 | X13: =IF(W13=0,0,IF(IF((S13>0)*(IF(T13="",-1,T13)>=1)*(IF(T13="",-1,T13)<=3),IF(C13="peso_corporal",IF(ISNUMBER(E13),E13,0)+R13,R13)*S13*1000+R13,0)=W13,5,IF(IF((P13>0)*(IF(Q13="",-1,Q13)>=1)*(IF(Q13="",-1,Q13)<=3),IF(C13="peso_corporal",IF(ISNUMBER(E13),E13,0)+O13,O13)*P13*1000+O13,0)=W13,4,IF(IF((M13>0)*(IF(N13="",-1,N13)>=1)*(IF(N13="",-1,N13)<=3),IF(C13="peso_corporal",IF(ISNUMBER(E13),E13,0)+L13,L13)*M13*1000+L13,0)=W13,3,IF(IF((J13>0)*(IF(K13="",-1,K13)>=1)*(IF(K13="",-1,K13)<=3),IF(C13="peso_corporal",IF(ISNUMBER(E13),E13,0)+I13,I13)*J13*1000+I13,0)=W13,2,IF(IF((G13>0)*(IF(H13="",-1,H13)>=1)*(IF(H13="",-1,H13)<=3),IF(C13="peso_corporal",IF(ISNUMBER(E13),E13,0)+F13,F13)*G13*1000+F13,0)=W13,1,0)))))) -> 0 | Y13: =MAX(IF((G13>0)*(IF(H13="",-1,H13)=0)*(1-(IF(H13="",-1,H13)>=1)*(IF(H13="",-1,H13)<=3)),IF(C13="peso_corporal",IF(ISNUMBER(E13),E13,0)+F13,F13)*G13*1000+F13,0),IF((J13>0)*(IF(K13="",-1,K13)=0)*(1-(IF(K13="",-1,K13)>=1)*(IF(K13="",-1,K13)<=3)),IF(C13="peso_corporal",IF(ISNUMBER(E13),E13,0)+I13,I13)*J13*1000+I13,0),IF((M13>0)*(IF(N13="",-1,N13)=0)*(1-(IF(N13="",-1,N13)>=1)*(IF(N13="",-1,N13)<=3)),IF(C13="peso_corporal",IF(ISNUMBER(E13),E13,0)+L13,L13)*M13*1000+L13,0),IF((P13>0)*(IF(Q13="",-1,Q13)=0)*(1-(IF(Q13="",-1,Q13)>=1)*(IF(Q13="",-1,Q13)<=3)),IF(C13="peso_corporal",IF(ISNUMBER(E13),E13,0)+O13,O13)*P13*1000+O13,0),IF((S13>0)*(IF(T13="",-1,T13)=0)*(1-(IF(T13="",-1,T13)>=1)*(IF(T13="",-1,T13)<=3)),IF(C13="peso_corporal",IF(ISNUMBER(E13),E13,0)+R13,R13)*S13*1000+R13,0)) -> 0 | Z13: =IF(Y13=0,0,IF(IF((S13>0)*(IF(T13="",-1,T13)=0)*(1-(IF(T13="",-1,T13)>=1)*(IF(T13="",-1,T13)<=3)),IF(C13="peso_corporal",IF(ISNUMBER(E13),E13,0)+R13,R13)*S13*1000+R13,0)=Y13,5,IF(IF((P13>0)*(IF(Q13="",-1,Q13)=0)*(1-(IF(Q13="",-1,Q13)>=1)*(IF(Q13="",-1,Q13)<=3)),IF(C13="peso_corporal",IF(ISNUMBER(E13),E13,0)+O13,O13)*P13*1000+O13,0)=Y13,4,IF(IF((M13>0)*(IF(N13="",-1,N13)=0)*(1-(IF(N13="",-1,N13)>=1)*(IF(N13="",-1,N13)<=3)),IF(C13="peso_corporal",IF(ISNUMBER(E13),E13,0)+L13,L13)*M13*1000+L13,0)=Y13,3,IF(IF((J13>0)*(IF(K13="",-1,K13)=0)*(1-(IF(K13="",-1,K13)>=1)*(IF(K13="",-1,K13)<=3)),IF(C13="peso_corporal",IF(ISNUMBER(E13),E13,0)+I13,I13)*J13*1000+I13,0)=Y13,2,IF(IF((G13>0)*(IF(H13="",-1,H13)=0)*(1-(IF(H13="",-1,H13)>=1)*(IF(H13="",-1,H13)<=3)),IF(C13="peso_corporal",IF(ISNUMBER(E13),E13,0)+F13,F13)*G13*1000+F13,0)=Y13,1,0)))))) -> 0 | AA13: =MAX(IF((G13>=6)*(1-(IF(H13="",-1,H13)>=1)*(IF(H13="",-1,H13)<=3))*(1-(IF(H13="",-1,H13)=0)),IF(C13="peso_corporal",IF(ISNUMBER(E13),E13,0)+F13,F13)*(30+G13)*100+F13,0),IF((J13>=6)*(1-(IF(K13="",-1,K13)>=1)*(IF(K13="",-1,K13)<=3))*(1-(IF(K13="",-1,K13)=0)),IF(C13="peso_corporal",IF(ISNUMBER(E13),E13,0)+I13,I13)*(30+J13)*100+I13,0),IF((M13>=6)*(1-(IF(N13="",-1,N13)>=1)*(IF(N13="",-1,N13)<=3))*(1-(IF(N13="",-1,N13)=0)),IF(C13="peso_corporal",IF(ISNUMBER(E13),E13,0)+L13,L13)*(30+M13)*100+L13,0),IF((P13>=6)*(1-(IF(Q13="",-1,Q13)>=1)*(IF(Q13="",-1,Q13)<=3))*(1-(IF(Q13="",-1,Q13)=0)),IF(C13="peso_corporal",IF(ISNUMBER(E13),E13,0)+O13,O13)*(30+P13)*100+O13,0),IF((S13>=6)*(1-(IF(T13="",-1,T13)>=1)*(IF(T13="",-1,T13)<=3))*(1-(IF(T13="",-1,T13)=0)),IF(C13="peso_corporal",IF(ISNUMBER(E13),E13,0)+R13,R13)*(30+S13)*100+R13,0)) -> 0 | AB13: =IF(AA13=0,0,IF(IF((S13>=6)*(1-(IF(T13="",-1,T13)>=1)*(IF(T13="",-1,T13)<=3))*(1-(IF(T13="",-1,T13)=0)),IF(C13="peso_corporal",IF(ISNUMBER(E13),E13,0)+R13,R13)*(30+S13)*100+R13,0)=AA13,5,IF(IF((P13>=6)*(1-(IF(Q13="",-1,Q13)>=1)*(IF(Q13="",-1,Q13)<=3))*(1-(IF(Q13="",-1,Q13)=0)),IF(C13="peso_corporal",IF(ISNUMBER(E13),E13,0)+O13,O13)*(30+P13)*100+O13,0)=AA13,4,IF(IF((M13>=6)*(1-(IF(N13="",-1,N13)>=1)*(IF(N13="",-1,N13)<=3))*(1-(IF(N13="",-1,N13)=0)),IF(C13="peso_corporal",IF(ISNUMBER(E13),E13,0)+L13,L13)*(30+M13)*100+L13,0)=AA13,3,IF(IF((J13>=6)*(1-(IF(K13="",-1,K13)>=1)*(IF(K13="",-1,K13)<=3))*(1-(IF(K13="",-1,K13)=0)),IF(C13="peso_corporal",IF(ISNUMBER(E13),E13,0)+I13,I13)*(30+J13)*100+I13,0)=AA13,2,IF(IF((G13>=6)*(1-(IF(H13="",-1,H13)>=1)*(IF(H13="",-1,H13)<=3))*(1-(IF(H13="",-1,H13)=0)),IF(C13="peso_corporal",IF(ISNUMBER(E13),E13,0)+F13,F13)*(30+G13)*100+F13,0)=AA13,1,0)))))) -> 0 | AC13: =IF(X13>0,"A"&X13,IF(Z13>0,"B"&Z13,IF(AB13>0,"C"&AB13,"")))
A14: · Alto
A15: Aperturas Inclinado | B15: Mancuernas Inclinado | C15: =IFERROR(INDEX(EJERCICIOS!$D$3:$D$75,MATCH(A15&"|"&B15,EJERCICIOS!$G$3:$G$75,0)),"--") -> mancuerna | D15: 3 | E15: =IFERROR(LOOKUP(2,1/(MEDIDAS_Y_PESO!$B$3:$B$3<>""),MEDIDAS_Y_PESO!$B$3:$B$3),"--") -> 80 | U15: =IFERROR(IF(IF(X15>0,X15,IF(Z15>0,Z15,IF(AB15>0,AB15,0)))=0,"--",ROUND(CHOOSE(IF(X15>0,X15,IF(Z15>0,Z15,IF(AB15>0,AB15,0))),IF(C15="peso_corporal",IF(ISNUMBER(E15),E15,0)+F15,F15)*(1+G15/30),IF(C15="peso_corporal",IF(ISNUMBER(E15),E15,0)+I15,I15)*(1+J15/30),IF(C15="peso_corporal",IF(ISNUMBER(E15),E15,0)+L15,L15)*(1+M15/30),IF(C15="peso_corporal",IF(ISNUMBER(E15),E15,0)+O15,O15)*(1+P15/30),IF(C15="peso_corporal",IF(ISNUMBER(E15),E15,0)+R15,R15)*(1+S15/30)),1)),"--") -> -- | V15: =IF(SUGERENCIAS!N5="SIN","Sin datos anteriores",IF(SUGERENCIAS!N5="SUBIR_F","^ SUBIR FUERTE | Kg:"&ROUND(SUGERENCIAS!K5,1)&" R:"&ROUND(SUGERENCIAS!L5,0)&" RIR:"&ROUND(SUGERENCIAS!M5,0),IF(SUGERENCIAS!N5="SUBIR_E","^ SUBIR (Est.) | Kg:"&ROUND(SUGERENCIAS!K5,1)&" R:"&ROUND(SUGERENCIAS!L5,0)&" RIR:"&ROUND(SUGERENCIAS!M5,0),IF(SUGERENCIAS!N5="SUBIR","^ SUBIR | Kg:"&ROUND(SUGERENCIAS!K5,1)&" R:"&ROUND(SUGERENCIAS!L5,0)&" RIR:"&ROUND(SUGERENCIAS!M5,0),IF(SUGERENCIAS!N5="BAJAR","v BAJAR | Kg:"&ROUND(SUGERENCIAS!K5,1)&" R:"&ROUND(SUGERENCIAS!L5,0)&" RIR:"&ROUND(SUGERENCIAS!M5,0),"= MANT | Kg:"&ROUND(SUGERENCIAS!K5,1)&" R:"&ROUND(SUGERENCIAS!L5,0)&" RIR:"&ROUND(SUGERENCIAS!M5,0)))))) -> Sin datos anteriores | W15: =MAX(IF((G15>0)*(IF(H15="",-1,H15)>=1)*(IF(H15="",-1,H15)<=3),IF(C15="peso_corporal",IF(ISNUMBER(E15),E15,0)+F15,F15)*G15*1000+F15,0),IF((J15>0)*(IF(K15="",-1,K15)>=1)*(IF(K15="",-1,K15)<=3),IF(C15="peso_corporal",IF(ISNUMBER(E15),E15,0)+I15,I15)*J15*1000+I15,0),IF((M15>0)*(IF(N15="",-1,N15)>=1)*(IF(N15="",-1,N15)<=3),IF(C15="peso_corporal",IF(ISNUMBER(E15),E15,0)+L15,L15)*M15*1000+L15,0),IF((P15>0)*(IF(Q15="",-1,Q15)>=1)*(IF(Q15="",-1,Q15)<=3),IF(C15="peso_corporal",IF(ISNUMBER(E15),E15,0)+O15,O15)*P15*1000+O15,0),IF((S15>0)*(IF(T15="",-1,T15)>=1)*(IF(T15="",-1,T15)<=3),IF(C15="peso_corporal",IF(ISNUMBER(E15),E15,0)+R15,R15)*S15*1000+R15,0)) -> 0 | X15: =IF(W15=0,0,IF(IF((S15>0)*(IF(T15="",-1,T15)>=1)*(IF(T15="",-1,T15)<=3),IF(C15="peso_corporal",IF(ISNUMBER(E15),E15,0)+R15,R15)*S15*1000+R15,0)=W15,5,IF(IF((P15>0)*(IF(Q15="",-1,Q15)>=1)*(IF(Q15="",-1,Q15)<=3),IF(C15="peso_corporal",IF(ISNUMBER(E15),E15,0)+O15,O15)*P15*1000+O15,0)=W15,4,IF(IF((M15>0)*(IF(N15="",-1,N15)>=1)*(IF(N15="",-1,N15)<=3),IF(C15="peso_corporal",IF(ISNUMBER(E15),E15,0)+L15,L15)*M15*1000+L15,0)=W15,3,IF(IF((J15>0)*(IF(K15="",-1,K15)>=1)*(IF(K15="",-1,K15)<=3),IF(C15="peso_corporal",IF(ISNUMBER(E15),E15,0)+I15,I15)*J15*1000+I15,0)=W15,2,IF(IF((G15>0)*(IF(H15="",-1,H15)>=1)*(IF(H15="",-1,H15)<=3),IF(C15="peso_corporal",IF(ISNUMBER(E15),E15,0)+F15,F15)*G15*1000+F15,0)=W15,1,0)))))) -> 0 | Y15: =MAX(IF((G15>0)*(IF(H15="",-1,H15)=0)*(1-(IF(H15="",-1,H15)>=1)*(IF(H15="",-1,H15)<=3)),IF(C15="peso_corporal",IF(ISNUMBER(E15),E15,0)+F15,F15)*G15*1000+F15,0),IF((J15>0)*(IF(K15="",-1,K15)=0)*(1-(IF(K15="",-1,K15)>=1)*(IF(K15="",-1,K15)<=3)),IF(C15="peso_corporal",IF(ISNUMBER(E15),E15,0)+I15,I15)*J15*1000+I15,0),IF((M15>0)*(IF(N15="",-1,N15)=0)*(1-(IF(N15="",-1,N15)>=1)*(IF(N15="",-1,N15)<=3)),IF(C15="peso_corporal",IF(ISNUMBER(E15),E15,0)+L15,L15)*M15*1000+L15,0),IF((P15>0)*(IF(Q15="",-1,Q15)=0)*(1-(IF(Q15="",-1,Q15)>=1)*(IF(Q15="",-1,Q15)<=3)),IF(C15="peso_corporal",IF(ISNUMBER(E15),E15,0)+O15,O15)*P15*1000+O15,0),IF((S15>0)*(IF(T15="",-1,T15)=0)*(1-(IF(T15="",-1,T15)>=1)*(IF(T15="",-1,T15)<=3)),IF(C15="peso_corporal",IF(ISNUMBER(E15),E15,0)+R15,R15)*S15*1000+R15,0)) -> 0 | Z15: =IF(Y15=0,0,IF(IF((S15>0)*(IF(T15="",-1,T15)=0)*(1-(IF(T15="",-1,T15)>=1)*(IF(T15="",-1,T15)<=3)),IF(C15="peso_corporal",IF(ISNUMBER(E15),E15,0)+R15,R15)*S15*1000+R15,0)=Y15,5,IF(IF((P15>0)*(IF(Q15="",-1,Q15)=0)*(1-(IF(Q15="",-1,Q15)>=1)*(IF(Q15="",-1,Q15)<=3)),IF(C15="peso_corporal",IF(ISNUMBER(E15),E15,0)+O15,O15)*P15*1000+O15,0)=Y15,4,IF(IF((M15>0)*(IF(N15="",-1,N15)=0)*(1-(IF(N15="",-1,N15)>=1)*(IF(N15="",-1,N15)<=3)),IF(C15="peso_corporal",IF(ISNUMBER(E15),E15,0)+L15,L15)*M15*1000+L15,0)=Y15,3,IF(IF((J15>0)*(IF(K15="",-1,K15)=0)*(1-(IF(K15="",-1,K15)>=1)*(IF(K15="",-1,K15)<=3)),IF(C15="peso_corporal",IF(ISNUMBER(E15),E15,0)+I15,I15)*J15*1000+I15,0)=Y15,2,IF(IF((G15>0)*(IF(H15="",-1,H15)=0)*(1-(IF(H15="",-1,H15)>=1)*(IF(H15="",-1,H15)<=3)),IF(C15="peso_corporal",IF(ISNUMBER(E15),E15,0)+F15,F15)*G15*1000+F15,0)=Y15,1,0)))))) -> 0 | AA15: =MAX(IF((G15>=6)*(1-(IF(H15="",-1,H15)>=1)*(IF(H15="",-1,H15)<=3))*(1-(IF(H15="",-1,H15)=0)),IF(C15="peso_corporal",IF(ISNUMBER(E15),E15,0)+F15,F15)*(30+G15)*100+F15,0),IF((J15>=6)*(1-(IF(K15="",-1,K15)>=1)*(IF(K15="",-1,K15)<=3))*(1-(IF(K15="",-1,K15)=0)),IF(C15="peso_corporal",IF(ISNUMBER(E15),E15,0)+I15,I15)*(30+J15)*100+I15,0),IF((M15>=6)*(1-(IF(N15="",-1,N15)>=1)*(IF(N15="",-1,N15)<=3))*(1-(IF(N15="",-1,N15)=0)),IF(C15="peso_corporal",IF(ISNUMBER(E15),E15,0)+L15,L15)*(30+M15)*100+L15,0),IF((P15>=6)*(1-(IF(Q15="",-1,Q15)>=1)*(IF(Q15="",-1,Q15)<=3))*(1-(IF(Q15="",-1,Q15)=0)),IF(C15="peso_corporal",IF(ISNUMBER(E15),E15,0)+O15,O15)*(30+P15)*100+O15,0),IF((S15>=6)*(1-(IF(T15="",-1,T15)>=1)*(IF(T15="",-1,T15)<=3))*(1-(IF(T15="",-1,T15)=0)),IF(C15="peso_corporal",IF(ISNUMBER(E15),E15,0)+R15,R15)*(30+S15)*100+R15,0)) -> 0 | AB15: =IF(AA15=0,0,IF(IF((S15>=6)*(1-(IF(T15="",-1,T15)>=1)*(IF(T15="",-1,T15)<=3))*(1-(IF(T15="",-1,T15)=0)),IF(C15="peso_corporal",IF(ISNUMBER(E15),E15,0)+R15,R15)*(30+S15)*100+R15,0)=AA15,5,IF(IF((P15>=6)*(1-(IF(Q15="",-1,Q15)>=1)*(IF(Q15="",-1,Q15)<=3))*(1-(IF(Q15="",-1,Q15)=0)),IF(C15="peso_corporal",IF(ISNUMBER(E15),E15,0)+O15,O15)*(30+P15)*100+O15,0)=AA15,4,IF(IF((M15>=6)*(1-(IF(N15="",-1,N15)>=1)*(IF(N15="",-1,N15)<=3))*(1-(IF(N15="",-1,N15)=0)),IF(C15="peso_corporal",IF(ISNUMBER(E15),E15,0)+L15,L15)*(30+M15)*100+L15,0)=AA15,3,IF(IF((J15>=6)*(1-(IF(K15="",-1,K15)>=1)*(IF(K15="",-1,K15)<=3))*(1-(IF(K15="",-1,K15)=0)),IF(C15="peso_corporal",IF(ISNUMBER(E15),E15,0)+I15,I15)*(30+J15)*100+I15,0)=AA15,2,IF(IF((G15>=6)*(1-(IF(H15="",-1,H15)>=1)*(IF(H15="",-1,H15)<=3))*(1-(IF(H15="",-1,H15)=0)),IF(C15="peso_corporal",IF(ISNUMBER(E15),E15,0)+F15,F15)*(30+G15)*100+F15,0)=AA15,1,0)))))) -> 0 | AC15: =IF(X15>0,"A"&X15,IF(Z15>0,"B"&Z15,IF(AB15>0,"C"&AB15,"")))
A16: · Bajo
A17: Fondos | B17: Paralelas | C17: =IFERROR(INDEX(EJERCICIOS!$D$3:$D$75,MATCH(A17&"|"&B17,EJERCICIOS!$G$3:$G$75,0)),"--") -> peso_corporal | D17: 3 | E17: =IFERROR(LOOKUP(2,1/(MEDIDAS_Y_PESO!$B$3:$B$3<>""),MEDIDAS_Y_PESO!$B$3:$B$3),"--") -> 80 | G17: 12 | H17: 0 | U17: =IFERROR(IF(IF(X17>0,X17,IF(Z17>0,Z17,IF(AB17>0,AB17,0)))=0,"--",ROUND(CHOOSE(IF(X17>0,X17,IF(Z17>0,Z17,IF(AB17>0,AB17,0))),IF(C17="peso_corporal",IF(ISNUMBER(E17),E17,0)+F17,F17)*(1+G17/30),IF(C17="peso_corporal",IF(ISNUMBER(E17),E17,0)+I17,I17)*(1+J17/30),IF(C17="peso_corporal",IF(ISNUMBER(E17),E17,0)+L17,L17)*(1+M17/30),IF(C17="peso_corporal",IF(ISNUMBER(E17),E17,0)+O17,O17)*(1+P17/30),IF(C17="peso_corporal",IF(ISNUMBER(E17),E17,0)+R17,R17)*(1+S17/30)),1)),"--") -> 112 | V17: =IF(SUGERENCIAS!N6="SIN","Sin datos anteriores",IF(SUGERENCIAS!N6="SUBIR_F","^ SUBIR FUERTE | Kg:"&ROUND(SUGERENCIAS!K6,1)&" R:"&ROUND(SUGERENCIAS!L6,0)&" RIR:"&ROUND(SUGERENCIAS!M6,0),IF(SUGERENCIAS!N6="SUBIR_E","^ SUBIR (Est.) | Kg:"&ROUND(SUGERENCIAS!K6,1)&" R:"&ROUND(SUGERENCIAS!L6,0)&" RIR:"&ROUND(SUGERENCIAS!M6,0),IF(SUGERENCIAS!N6="SUBIR","^ SUBIR | Kg:"&ROUND(SUGERENCIAS!K6,1)&" R:"&ROUND(SUGERENCIAS!L6,0)&" RIR:"&ROUND(SUGERENCIAS!M6,0),IF(SUGERENCIAS!N6="BAJAR","v BAJAR | Kg:"&ROUND(SUGERENCIAS!K6,1)&" R:"&ROUND(SUGERENCIAS!L6,0)&" RIR:"&ROUND(SUGERENCIAS!M6,0),"= MANT | Kg:"&ROUND(SUGERENCIAS!K6,1)&" R:"&ROUND(SUGERENCIAS!L6,0)&" RIR:"&ROUND(SUGERENCIAS!M6,0)))))) -> Sin datos anteriores | W17: =MAX(IF((G17>0)*(IF(H17="",-1,H17)>=1)*(IF(H17="",-1,H17)<=3),IF(C17="peso_corporal",IF(ISNUMBER(E17),E17,0)+F17,F17)*G17*1000+F17,0),IF((J17>0)*(IF(K17="",-1,K17)>=1)*(IF(K17="",-1,K17)<=3),IF(C17="peso_corporal",IF(ISNUMBER(E17),E17,0)+I17,I17)*J17*1000+I17,0),IF((M17>0)*(IF(N17="",-1,N17)>=1)*(IF(N17="",-1,N17)<=3),IF(C17="peso_corporal",IF(ISNUMBER(E17),E17,0)+L17,L17)*M17*1000+L17,0),IF((P17>0)*(IF(Q17="",-1,Q17)>=1)*(IF(Q17="",-1,Q17)<=3),IF(C17="peso_corporal",IF(ISNUMBER(E17),E17,0)+O17,O17)*P17*1000+O17,0),IF((S17>0)*(IF(T17="",-1,T17)>=1)*(IF(T17="",-1,T17)<=3),IF(C17="peso_corporal",IF(ISNUMBER(E17),E17,0)+R17,R17)*S17*1000+R17,0)) -> 0 | X17: =IF(W17=0,0,IF(IF((S17>0)*(IF(T17="",-1,T17)>=1)*(IF(T17="",-1,T17)<=3),IF(C17="peso_corporal",IF(ISNUMBER(E17),E17,0)+R17,R17)*S17*1000+R17,0)=W17,5,IF(IF((P17>0)*(IF(Q17="",-1,Q17)>=1)*(IF(Q17="",-1,Q17)<=3),IF(C17="peso_corporal",IF(ISNUMBER(E17),E17,0)+O17,O17)*P17*1000+O17,0)=W17,4,IF(IF((M17>0)*(IF(N17="",-1,N17)>=1)*(IF(N17="",-1,N17)<=3),IF(C17="peso_corporal",IF(ISNUMBER(E17),E17,0)+L17,L17)*M17*1000+L17,0)=W17,3,IF(IF((J17>0)*(IF(K17="",-1,K17)>=1)*(IF(K17="",-1,K17)<=3),IF(C17="peso_corporal",IF(ISNUMBER(E17),E17,0)+I17,I17)*J17*1000+I17,0)=W17,2,IF(IF((G17>0)*(IF(H17="",-1,H17)>=1)*(IF(H17="",-1,H17)<=3),IF(C17="peso_corporal",IF(ISNUMBER(E17),E17,0)+F17,F17)*G17*1000+F17,0)=W17,1,0)))))) -> 0 | Y17: =MAX(IF((G17>0)*(IF(H17="",-1,H17)=0)*(1-(IF(H17="",-1,H17)>=1)*(IF(H17="",-1,H17)<=3)),IF(C17="peso_corporal",IF(ISNUMBER(E17),E17,0)+F17,F17)*G17*1000+F17,0),IF((J17>0)*(IF(K17="",-1,K17)=0)*(1-(IF(K17="",-1,K17)>=1)*(IF(K17="",-1,K17)<=3)),IF(C17="peso_corporal",IF(ISNUMBER(E17),E17,0)+I17,I17)*J17*1000+I17,0),IF((M17>0)*(IF(N17="",-1,N17)=0)*(1-(IF(N17="",-1,N17)>=1)*(IF(N17="",-1,N17)<=3)),IF(C17="peso_corporal",IF(ISNUMBER(E17),E17,0)+L17,L17)*M17*1000+L17,0),IF((P17>0)*(IF(Q17="",-1,Q17)=0)*(1-(IF(Q17="",-1,Q17)>=1)*(IF(Q17="",-1,Q17)<=3)),IF(C17="peso_corporal",IF(ISNUMBER(E17),E17,0)+O17,O17)*P17*1000+O17,0),IF((S17>0)*(IF(T17="",-1,T17)=0)*(1-(IF(T17="",-1,T17)>=1)*(IF(T17="",-1,T17)<=3)),IF(C17="peso_corporal",IF(ISNUMBER(E17),E17,0)+R17,R17)*S17*1000+R17,0)) -> 960000 | Z17: =IF(Y17=0,0,IF(IF((S17>0)*(IF(T17="",-1,T17)=0)*(1-(IF(T17="",-1,T17)>=1)*(IF(T17="",-1,T17)<=3)),IF(C17="peso_corporal",IF(ISNUMBER(E17),E17,0)+R17,R17)*S17*1000+R17,0)=Y17,5,IF(IF((P17>0)*(IF(Q17="",-1,Q17)=0)*(1-(IF(Q17="",-1,Q17)>=1)*(IF(Q17="",-1,Q17)<=3)),IF(C17="peso_corporal",IF(ISNUMBER(E17),E17,0)+O17,O17)*P17*1000+O17,0)=Y17,4,IF(IF((M17>0)*(IF(N17="",-1,N17)=0)*(1-(IF(N17="",-1,N17)>=1)*(IF(N17="",-1,N17)<=3)),IF(C17="peso_corporal",IF(ISNUMBER(E17),E17,0)+L17,L17)*M17*1000+L17,0)=Y17,3,IF(IF((J17>0)*(IF(K17="",-1,K17)=0)*(1-(IF(K17="",-1,K17)>=1)*(IF(K17="",-1,K17)<=3)),IF(C17="peso_corporal",IF(ISNUMBER(E17),E17,0)+I17,I17)*J17*1000+I17,0)=Y17,2,IF(IF((G17>0)*(IF(H17="",-1,H17)=0)*(1-(IF(H17="",-1,H17)>=1)*(IF(H17="",-1,H17)<=3)),IF(C17="peso_corporal",IF(ISNUMBER(E17),E17,0)+F17,F17)*G17*1000+F17,0)=Y17,1,0)))))) -> 1 | AA17: =MAX(IF((G17>=6)*(1-(IF(H17="",-1,H17)>=1)*(IF(H17="",-1,H17)<=3))*(1-(IF(H17="",-1,H17)=0)),IF(C17="peso_corporal",IF(ISNUMBER(E17),E17,0)+F17,F17)*(30+G17)*100+F17,0),IF((J17>=6)*(1-(IF(K17="",-1,K17)>=1)*(IF(K17="",-1,K17)<=3))*(1-(IF(K17="",-1,K17)=0)),IF(C17="peso_corporal",IF(ISNUMBER(E17),E17,0)+I17,I17)*(30+J17)*100+I17,0),IF((M17>=6)*(1-(IF(N17="",-1,N17)>=1)*(IF(N17="",-1,N17)<=3))*(1-(IF(N17="",-1,N17)=0)),IF(C17="peso_corporal",IF(ISNUMBER(E17),E17,0)+L17,L17)*(30+M17)*100+L17,0),IF((P17>=6)*(1-(IF(Q17="",-1,Q17)>=1)*(IF(Q17="",-1,Q17)<=3))*(1-(IF(Q17="",-1,Q17)=0)),IF(C17="peso_corporal",IF(ISNUMBER(E17),E17,0)+O17,O17)*(30+P17)*100+O17,0),IF((S17>=6)*(1-(IF(T17="",-1,T17)>=1)*(IF(T17="",-1,T17)<=3))*(1-(IF(T17="",-1,T17)=0)),IF(C17="peso_corporal",IF(ISNUMBER(E17),E17,0)+R17,R17)*(30+S17)*100+R17,0)) -> 0 | AB17: =IF(AA17=0,0,IF(IF((S17>=6)*(1-(IF(T17="",-1,T17)>=1)*(IF(T17="",-1,T17)<=3))*(1-(IF(T17="",-1,T17)=0)),IF(C17="peso_corporal",IF(ISNUMBER(E17),E17,0)+R17,R17)*(30+S17)*100+R17,0)=AA17,5,IF(IF((P17>=6)*(1-(IF(Q17="",-1,Q17)>=1)*(IF(Q17="",-1,Q17)<=3))*(1-(IF(Q17="",-1,Q17)=0)),IF(C17="peso_corporal",IF(ISNUMBER(E17),E17,0)+O17,O17)*(30+P17)*100+O17,0)=AA17,4,IF(IF((M17>=6)*(1-(IF(N17="",-1,N17)>=1)*(IF(N17="",-1,N17)<=3))*(1-(IF(N17="",-1,N17)=0)),IF(C17="peso_corporal",IF(ISNUMBER(E17),E17,0)+L17,L17)*(30+M17)*100+L17,0)=AA17,3,IF(IF((J17>=6)*(1-(IF(K17="",-1,K17)>=1)*(IF(K17="",-1,K17)<=3))*(1-(IF(K17="",-1,K17)=0)),IF(C17="peso_corporal",IF(ISNUMBER(E17),E17,0)+I17,I17)*(30+J17)*100+I17,0)=AA17,2,IF(IF((G17>=6)*(1-(IF(H17="",-1,H17)>=1)*(IF(H17="",-1,H17)<=3))*(1-(IF(H17="",-1,H17)=0)),IF(C17="peso_corporal",IF(ISNUMBER(E17),E17,0)+F17,F17)*(30+G17)*100+F17,0)=AA17,1,0)))))) -> 0 | AC17: =IF(X17>0,"A"&X17,IF(Z17>0,"B"&Z17,IF(AB17>0,"C"&AB17,""))) -> B1
A18: Aperturas Bajo | B18: Polea Baja Crossover | C18: =IFERROR(INDEX(EJERCICIOS!$D$3:$D$75,MATCH(A18&"|"&B18,EJERCICIOS!$G$3:$G$75,0)),"--") -> polea | D18: 3 | E18: =IFERROR(LOOKUP(2,1/(MEDIDAS_Y_PESO!$B$3:$B$3<>""),MEDIDAS_Y_PESO!$B$3:$B$3),"--") -> 80 | U18: =IFERROR(IF(IF(X18>0,X18,IF(Z18>0,Z18,IF(AB18>0,AB18,0)))=0,"--",ROUND(CHOOSE(IF(X18>0,X18,IF(Z18>0,Z18,IF(AB18>0,AB18,0))),IF(C18="peso_corporal",IF(ISNUMBER(E18),E18,0)+F18,F18)*(1+G18/30),IF(C18="peso_corporal",IF(ISNUMBER(E18),E18,0)+I18,I18)*(1+J18/30),IF(C18="peso_corporal",IF(ISNUMBER(E18),E18,0)+L18,L18)*(1+M18/30),IF(C18="peso_corporal",IF(ISNUMBER(E18),E18,0)+O18,O18)*(1+P18/30),IF(C18="peso_corporal",IF(ISNUMBER(E18),E18,0)+R18,R18)*(1+S18/30)),1)),"--") -> -- | V18: =IF(SUGERENCIAS!N7="SIN","Sin datos anteriores",IF(SUGERENCIAS!N7="SUBIR_F","^ SUBIR FUERTE | Kg:"&ROUND(SUGERENCIAS!K7,1)&" R:"&ROUND(SUGERENCIAS!L7,0)&" RIR:"&ROUND(SUGERENCIAS!M7,0),IF(SUGERENCIAS!N7="SUBIR_E","^ SUBIR (Est.) | Kg:"&ROUND(SUGERENCIAS!K7,1)&" R:"&ROUND(SUGERENCIAS!L7,0)&" RIR:"&ROUND(SUGERENCIAS!M7,0),IF(SUGERENCIAS!N7="SUBIR","^ SUBIR | Kg:"&ROUND(SUGERENCIAS!K7,1)&" R:"&ROUND(SUGERENCIAS!L7,0)&" RIR:"&ROUND(SUGERENCIAS!M7,0),IF(SUGERENCIAS!N7="BAJAR","v BAJAR | Kg:"&ROUND(SUGERENCIAS!K7,1)&" R:"&ROUND(SUGERENCIAS!L7,0)&" RIR:"&ROUND(SUGERENCIAS!M7,0),"= MANT | Kg:"&ROUND(SUGERENCIAS!K7,1)&" R:"&ROUND(SUGERENCIAS!L7,0)&" RIR:"&ROUND(SUGERENCIAS!M7,0)))))) -> Sin datos anteriores | W18: =MAX(IF((G18>0)*(IF(H18="",-1,H18)>=1)*(IF(H18="",-1,H18)<=3),IF(C18="peso_corporal",IF(ISNUMBER(E18),E18,0)+F18,F18)*G18*1000+F18,0),IF((J18>0)*(IF(K18="",-1,K18)>=1)*(IF(K18="",-1,K18)<=3),IF(C18="peso_corporal",IF(ISNUMBER(E18),E18,0)+I18,I18)*J18*1000+I18,0),IF((M18>0)*(IF(N18="",-1,N18)>=1)*(IF(N18="",-1,N18)<=3),IF(C18="peso_corporal",IF(ISNUMBER(E18),E18,0)+L18,L18)*M18*1000+L18,0),IF((P18>0)*(IF(Q18="",-1,Q18)>=1)*(IF(Q18="",-1,Q18)<=3),IF(C18="peso_corporal",IF(ISNUMBER(E18),E18,0)+O18,O18)*P18*1000+O18,0),IF((S18>0)*(IF(T18="",-1,T18)>=1)*(IF(T18="",-1,T18)<=3),IF(C18="peso_corporal",IF(ISNUMBER(E18),E18,0)+R18,R18)*S18*1000+R18,0)) -> 0 | X18: =IF(W18=0,0,IF(IF((S18>0)*(IF(T18="",-1,T18)>=1)*(IF(T18="",-1,T18)<=3),IF(C18="peso_corporal",IF(ISNUMBER(E18),E18,0)+R18,R18)*S18*1000+R18,0)=W18,5,IF(IF((P18>0)*(IF(Q18="",-1,Q18)>=1)*(IF(Q18="",-1,Q18)<=3),IF(C18="peso_corporal",IF(ISNUMBER(E18),E18,0)+O18,O18)*P18*1000+O18,0)=W18,4,IF(IF((M18>0)*(IF(N18="",-1,N18)>=1)*(IF(N18="",-1,N18)<=3),IF(C18="peso_corporal",IF(ISNUMBER(E18),E18,0)+L18,L18)*M18*1000+L18,0)=W18,3,IF(IF((J18>0)*(IF(K18="",-1,K18)>=1)*(IF(K18="",-1,K18)<=3),IF(C18="peso_corporal",IF(ISNUMBER(E18),E18,0)+I18,I18)*J18*1000+I18,0)=W18,2,IF(IF((G18>0)*(IF(H18="",-1,H18)>=1)*(IF(H18="",-1,H18)<=3),IF(C18="peso_corporal",IF(ISNUMBER(E18),E18,0)+F18,F18)*G18*1000+F18,0)=W18,1,0)))))) -> 0 | Y18: =MAX(IF((G18>0)*(IF(H18="",-1,H18)=0)*(1-(IF(H18="",-1,H18)>=1)*(IF(H18="",-1,H18)<=3)),IF(C18="peso_corporal",IF(ISNUMBER(E18),E18,0)+F18,F18)*G18*1000+F18,0),IF((J18>0)*(IF(K18="",-1,K18)=0)*(1-(IF(K18="",-1,K18)>=1)*(IF(K18="",-1,K18)<=3)),IF(C18="peso_corporal",IF(ISNUMBER(E18),E18,0)+I18,I18)*J18*1000+I18,0),IF((M18>0)*(IF(N18="",-1,N18)=0)*(1-(IF(N18="",-1,N18)>=1)*(IF(N18="",-1,N18)<=3)),IF(C18="peso_corporal",IF(ISNUMBER(E18),E18,0)+L18,L18)*M18*1000+L18,0),IF((P18>0)*(IF(Q18="",-1,Q18)=0)*(1-(IF(Q18="",-1,Q18)>=1)*(IF(Q18="",-1,Q18)<=3)),IF(C18="peso_corporal",IF(ISNUMBER(E18),E18,0)+O18,O18)*P18*1000+O18,0),IF((S18>0)*(IF(T18="",-1,T18)=0)*(1-(IF(T18="",-1,T18)>=1)*(IF(T18="",-1,T18)<=3)),IF(C18="peso_corporal",IF(ISNUMBER(E18),E18,0)+R18,R18)*S18*1000+R18,0)) -> 0 | Z18: =IF(Y18=0,0,IF(IF((S18>0)*(IF(T18="",-1,T18)=0)*(1-(IF(T18="",-1,T18)>=1)*(IF(T18="",-1,T18)<=3)),IF(C18="peso_corporal",IF(ISNUMBER(E18),E18,0)+R18,R18)*S18*1000+R18,0)=Y18,5,IF(IF((P18>0)*(IF(Q18="",-1,Q18)=0)*(1-(IF(Q18="",-1,Q18)>=1)*(IF(Q18="",-1,Q18)<=3)),IF(C18="peso_corporal",IF(ISNUMBER(E18),E18,0)+O18,O18)*P18*1000+O18,0)=Y18,4,IF(IF((M18>0)*(IF(N18="",-1,N18)=0)*(1-(IF(N18="",-1,N18)>=1)*(IF(N18="",-1,N18)<=3)),IF(C18="peso_corporal",IF(ISNUMBER(E18),E18,0)+L18,L18)*M18*1000+L18,0)=Y18,3,IF(IF((J18>0)*(IF(K18="",-1,K18)=0)*(1-(IF(K18="",-1,K18)>=1)*(IF(K18="",-1,K18)<=3)),IF(C18="peso_corporal",IF(ISNUMBER(E18),E18,0)+I18,I18)*J18*1000+I18,0)=Y18,2,IF(IF((G18>0)*(IF(H18="",-1,H18)=0)*(1-(IF(H18="",-1,H18)>=1)*(IF(H18="",-1,H18)<=3)),IF(C18="peso_corporal",IF(ISNUMBER(E18),E18,0)+F18,F18)*G18*1000+F18,0)=Y18,1,0)))))) -> 0 | AA18: =MAX(IF((G18>=6)*(1-(IF(H18="",-1,H18)>=1)*(IF(H18="",-1,H18)<=3))*(1-(IF(H18="",-1,H18)=0)),IF(C18="peso_corporal",IF(ISNUMBER(E18),E18,0)+F18,F18)*(30+G18)*100+F18,0),IF((J18>=6)*(1-(IF(K18="",-1,K18)>=1)*(IF(K18="",-1,K18)<=3))*(1-(IF(K18="",-1,K18)=0)),IF(C18="peso_corporal",IF(ISNUMBER(E18),E18,0)+I18,I18)*(30+J18)*100+I18,0),IF((M18>=6)*(1-(IF(N18="",-1,N18)>=1)*(IF(N18="",-1,N18)<=3))*(1-(IF(N18="",-1,N18)=0)),IF(C18="peso_corporal",IF(ISNUMBER(E18),E18,0)+L18,L18)*(30+M18)*100+L18,0),IF((P18>=6)*(1-(IF(Q18="",-1,Q18)>=1)*(IF(Q18="",-1,Q18)<=3))*(1-(IF(Q18="",-1,Q18)=0)),IF(C18="peso_corporal",IF(ISNUMBER(E18),E18,0)+O18,O18)*(30+P18)*100+O18,0),IF((S18>=6)*(1-(IF(T18="",-1,T18)>=1)*(IF(T18="",-1,T18)<=3))*(1-(IF(T18="",-1,T18)=0)),IF(C18="peso_corporal",IF(ISNUMBER(E18),E18,0)+R18,R18)*(30+S18)*100+R18,0)) -> 0 | AB18: =IF(AA18=0,0,IF(IF((S18>=6)*(1-(IF(T18="",-1,T18)>=1)*(IF(T18="",-1,T18)<=3))*(1-(IF(T18="",-1,T18)=0)),IF(C18="peso_corporal",IF(ISNUMBER(E18),E18,0)+R18,R18)*(30+S18)*100+R18,0)=AA18,5,IF(IF((P18>=6)*(1-(IF(Q18="",-1,Q18)>=1)*(IF(Q18="",-1,Q18)<=3))*(1-(IF(Q18="",-1,Q18)=0)),IF(C18="peso_corporal",IF(ISNUMBER(E18),E18,0)+O18,O18)*(30+P18)*100+O18,0)=AA18,4,IF(IF((M18>=6)*(1-(IF(N18="",-1,N18)>=1)*(IF(N18="",-1,N18)<=3))*(1-(IF(N18="",-1,N18)=0)),IF(C18="peso_corporal",IF(ISNUMBER(E18),E18,0)+L18,L18)*(30+M18)*100+L18,0)=AA18,3,IF(IF((J18>=6)*(1-(IF(K18="",-1,K18)>=1)*(IF(K18="",-1,K18)<=3))*(1-(IF(K18="",-1,K18)=0)),IF(C18="peso_corporal",IF(ISNUMBER(E18),E18,0)+I18,I18)*(30+J18)*100+I18,0)=AA18,2,IF(IF((G18>=6)*(1-(IF(H18="",-1,H18)>=1)*(IF(H18="",-1,H18)<=3))*(1-(IF(H18="",-1,H18)=0)),IF(C18="peso_corporal",IF(ISNUMBER(E18),E18,0)+F18,F18)*(30+G18)*100+F18,0)=AA18,1,0)))))) -> 0 | AC18: =IF(X18>0,"A"&X18,IF(Z18>0,"B"&Z18,IF(AB18>0,"C"&AB18,"")))
A19: Press Polea | B19: Barra Recta Diagonal Arriba | C19: =IFERROR(INDEX(EJERCICIOS!$D$3:$D$75,MATCH(A19&"|"&B19,EJERCICIOS!$G$3:$G$75,0)),"--") -> polea | D19: 3 | E19: =IFERROR(LOOKUP(2,1/(MEDIDAS_Y_PESO!$B$3:$B$3<>""),MEDIDAS_Y_PESO!$B$3:$B$3),"--") -> 80 | U19: =IFERROR(IF(IF(X19>0,X19,IF(Z19>0,Z19,IF(AB19>0,AB19,0)))=0,"--",ROUND(CHOOSE(IF(X19>0,X19,IF(Z19>0,Z19,IF(AB19>0,AB19,0))),IF(C19="peso_corporal",IF(ISNUMBER(E19),E19,0)+F19,F19)*(1+G19/30),IF(C19="peso_corporal",IF(ISNUMBER(E19),E19,0)+I19,I19)*(1+J19/30),IF(C19="peso_corporal",IF(ISNUMBER(E19),E19,0)+L19,L19)*(1+M19/30),IF(C19="peso_corporal",IF(ISNUMBER(E19),E19,0)+O19,O19)*(1+P19/30),IF(C19="peso_corporal",IF(ISNUMBER(E19),E19,0)+R19,R19)*(1+S19/30)),1)),"--") -> -- | V19: =IF(SUGERENCIAS!N8="SIN","Sin datos anteriores",IF(SUGERENCIAS!N8="SUBIR_F","^ SUBIR FUERTE | Kg:"&ROUND(SUGERENCIAS!K8,1)&" R:"&ROUND(SUGERENCIAS!L8,0)&" RIR:"&ROUND(SUGERENCIAS!M8,0),IF(SUGERENCIAS!N8="SUBIR_E","^ SUBIR (Est.) | Kg:"&ROUND(SUGERENCIAS!K8,1)&" R:"&ROUND(SUGERENCIAS!L8,0)&" RIR:"&ROUND(SUGERENCIAS!M8,0),IF(SUGERENCIAS!N8="SUBIR","^ SUBIR | Kg:"&ROUND(SUGERENCIAS!K8,1)&" R:"&ROUND(SUGERENCIAS!L8,0)&" RIR:"&ROUND(SUGERENCIAS!M8,0),IF(SUGERENCIAS!N8="BAJAR","v BAJAR | Kg:"&ROUND(SUGERENCIAS!K8,1)&" R:"&ROUND(SUGERENCIAS!L8,0)&" RIR:"&ROUND(SUGERENCIAS!M8,0),"= MANT | Kg:"&ROUND(SUGERENCIAS!K8,1)&" R:"&ROUND(SUGERENCIAS!L8,0)&" RIR:"&ROUND(SUGERENCIAS!M8,0)))))) -> Sin datos anteriores | W19: =MAX(IF((G19>0)*(IF(H19="",-1,H19)>=1)*(IF(H19="",-1,H19)<=3),IF(C19="peso_corporal",IF(ISNUMBER(E19),E19,0)+F19,F19)*G19*1000+F19,0),IF((J19>0)*(IF(K19="",-1,K19)>=1)*(IF(K19="",-1,K19)<=3),IF(C19="peso_corporal",IF(ISNUMBER(E19),E19,0)+I19,I19)*J19*1000+I19,0),IF((M19>0)*(IF(N19="",-1,N19)>=1)*(IF(N19="",-1,N19)<=3),IF(C19="peso_corporal",IF(ISNUMBER(E19),E19,0)+L19,L19)*M19*1000+L19,0),IF((P19>0)*(IF(Q19="",-1,Q19)>=1)*(IF(Q19="",-1,Q19)<=3),IF(C19="peso_corporal",IF(ISNUMBER(E19),E19,0)+O19,O19)*P19*1000+O19,0),IF((S19>0)*(IF(T19="",-1,T19)>=1)*(IF(T19="",-1,T19)<=3),IF(C19="peso_corporal",IF(ISNUMBER(E19),E19,0)+R19,R19)*S19*1000+R19,0)) -> 0 | X19: =IF(W19=0,0,IF(IF((S19>0)*(IF(T19="",-1,T19)>=1)*(IF(T19="",-1,T19)<=3),IF(C19="peso_corporal",IF(ISNUMBER(E19),E19,0)+R19,R19)*S19*1000+R19,0)=W19,5,IF(IF((P19>0)*(IF(Q19="",-1,Q19)>=1)*(IF(Q19="",-1,Q19)<=3),IF(C19="peso_corporal",IF(ISNUMBER(E19),E19,0)+O19,O19)*P19*1000+O19,0)=W19,4,IF(IF((M19>0)*(IF(N19="",-1,N19)>=1)*(IF(N19="",-1,N19)<=3),IF(C19="peso_corporal",IF(ISNUMBER(E19),E19,0)+L19,L19)*M19*1000+L19,0)=W19,3,IF(IF((J19>0)*(IF(K19="",-1,K19)>=1)*(IF(K19="",-1,K19)<=3),IF(C19="peso_corporal",IF(ISNUMBER(E19),E19,0)+I19,I19)*J19*1000+I19,0)=W19,2,IF(IF((G19>0)*(IF(H19="",-1,H19)>=1)*(IF(H19="",-1,H19)<=3),IF(C19="peso_corporal",IF(ISNUMBER(E19),E19,0)+F19,F19)*G19*1000+F19,0)=W19,1,0)))))) -> 0 | Y19: =MAX(IF((G19>0)*(IF(H19="",-1,H19)=0)*(1-(IF(H19="",-1,H19)>=1)*(IF(H19="",-1,H19)<=3)),IF(C19="peso_corporal",IF(ISNUMBER(E19),E19,0)+F19,F19)*G19*1000+F19,0),IF((J19>0)*(IF(K19="",-1,K19)=0)*(1-(IF(K19="",-1,K19)>=1)*(IF(K19="",-1,K19)<=3)),IF(C19="peso_corporal",IF(ISNUMBER(E19),E19,0)+I19,I19)*J19*1000+I19,0),IF((M19>0)*(IF(N19="",-1,N19)=0)*(1-(IF(N19="",-1,N19)>=1)*(IF(N19="",-1,N19)<=3)),IF(C19="peso_corporal",IF(ISNUMBER(E19),E19,0)+L19,L19)*M19*1000+L19,0),IF((P19>0)*(IF(Q19="",-1,Q19)=0)*(1-(IF(Q19="",-1,Q19)>=1)*(IF(Q19="",-1,Q19)<=3)),IF(C19="peso_corporal",IF(ISNUMBER(E19),E19,0)+O19,O19)*P19*1000+O19,0),IF((S19>0)*(IF(T19="",-1,T19)=0)*(1-(IF(T19="",-1,T19)>=1)*(IF(T19="",-1,T19)<=3)),IF(C19="peso_corporal",IF(ISNUMBER(E19),E19,0)+R19,R19)*S19*1000+R19,0)) -> 0 | Z19: =IF(Y19=0,0,IF(IF((S19>0)*(IF(T19="",-1,T19)=0)*(1-(IF(T19="",-1,T19)>=1)*(IF(T19="",-1,T19)<=3)),IF(C19="peso_corporal",IF(ISNUMBER(E19),E19,0)+R19,R19)*S19*1000+R19,0)=Y19,5,IF(IF((P19>0)*(IF(Q19="",-1,Q19)=0)*(1-(IF(Q19="",-1,Q19)>=1)*(IF(Q19="",-1,Q19)<=3)),IF(C19="peso_corporal",IF(ISNUMBER(E19),E19,0)+O19,O19)*P19*1000+O19,0)=Y19,4,IF(IF((M19>0)*(IF(N19="",-1,N19)=0)*(1-(IF(N19="",-1,N19)>=1)*(IF(N19="",-1,N19)<=3)),IF(C19="peso_corporal",IF(ISNUMBER(E19),E19,0)+L19,L19)*M19*1000+L19,0)=Y19,3,IF(IF((J19>0)*(IF(K19="",-1,K19)=0)*(1-(IF(K19="",-1,K19)>=1)*(IF(K19="",-1,K19)<=3)),IF(C19="peso_corporal",IF(ISNUMBER(E19),E19,0)+I19,I19)*J19*1000+I19,0)=Y19,2,IF(IF((G19>0)*(IF(H19="",-1,H19)=0)*(1-(IF(H19="",-1,H19)>=1)*(IF(H19="",-1,H19)<=3)),IF(C19="peso_corporal",IF(ISNUMBER(E19),E19,0)+F19,F19)*G19*1000+F19,0)=Y19,1,0)))))) -> 0 | AA19: =MAX(IF((G19>=6)*(1-(IF(H19="",-1,H19)>=1)*(IF(H19="",-1,H19)<=3))*(1-(IF(H19="",-1,H19)=0)),IF(C19="peso_corporal",IF(ISNUMBER(E19),E19,0)+F19,F19)*(30+G19)*100+F19,0),IF((J19>=6)*(1-(IF(K19="",-1,K19)>=1)*(IF(K19="",-1,K19)<=3))*(1-(IF(K19="",-1,K19)=0)),IF(C19="peso_corporal",IF(ISNUMBER(E19),E19,0)+I19,I19)*(30+J19)*100+I19,0),IF((M19>=6)*(1-(IF(N19="",-1,N19)>=1)*(IF(N19="",-1,N19)<=3))*(1-(IF(N19="",-1,N19)=0)),IF(C19="peso_corporal",IF(ISNUMBER(E19),E19,0)+L19,L19)*(30+M19)*100+L19,0),IF((P19>=6)*(1-(IF(Q19="",-1,Q19)>=1)*(IF(Q19="",-1,Q19)<=3))*(1-(IF(Q19="",-1,Q19)=0)),IF(C19="peso_corporal",IF(ISNUMBER(E19),E19,0)+O19,O19)*(30+P19)*100+O19,0),IF((S19>=6)*(1-(IF(T19="",-1,T19)>=1)*(IF(T19="",-1,T19)<=3))*(1-(IF(T19="",-1,T19)=0)),IF(C19="peso_corporal",IF(ISNUMBER(E19),E19,0)+R19,R19)*(30+S19)*100+R19,0)) -> 0 | AB19: =IF(AA19=0,0,IF(IF((S19>=6)*(1-(IF(T19="",-1,T19)>=1)*(IF(T19="",-1,T19)<=3))*(1-(IF(T19="",-1,T19)=0)),IF(C19="peso_corporal",IF(ISNUMBER(E19),E19,0)+R19,R19)*(30+S19)*100+R19,0)=AA19,5,IF(IF((P19>=6)*(1-(IF(Q19="",-1,Q19)>=1)*(IF(Q19="",-1,Q19)<=3))*(1-(IF(Q19="",-1,Q19)=0)),IF(C19="peso_corporal",IF(ISNUMBER(E19),E19,0)+O19,O19)*(30+P19)*100+O19,0)=AA19,4,IF(IF((M19>=6)*(1-(IF(N19="",-1,N19)>=1)*(IF(N19="",-1,N19)<=3))*(1-(IF(N19="",-1,N19)=0)),IF(C19="peso_corporal",IF(ISNUMBER(E19),E19,0)+L19,L19)*(30+M19)*100+L19,0)=AA19,3,IF(IF((J19>=6)*(1-(IF(K19="",-1,K19)>=1)*(IF(K19="",-1,K19)<=3))*(1-(IF(K19="",-1,K19)=0)),IF(C19="peso_corporal",IF(ISNUMBER(E19),E19,0)+I19,I19)*(30+J19)*100+I19,0)=AA19,2,IF(IF((G19>=6)*(1-(IF(H19="",-1,H19)>=1)*(IF(H19="",-1,H19)<=3))*(1-(IF(H19="",-1,H19)=0)),IF(C19="peso_corporal",IF(ISNUMBER(E19),E19,0)+F19,F19)*(30+G19)*100+F19,0)=AA19,1,0)))))) -> 0 | AC19: =IF(X19>0,"A"&X19,IF(Z19>0,"B"&Z19,IF(AB19>0,"C"&AB19,"")))
A20: — HOMBRO —
A21: Elevaciones Laterales | B21: Cable Polea Individual | C21: =IFERROR(INDEX(EJERCICIOS!$D$3:$D$75,MATCH(A21&"|"&B21,EJERCICIOS!$G$3:$G$75,0)),"--") -> polea | D21: 3 | E21: =IFERROR(LOOKUP(2,1/(MEDIDAS_Y_PESO!$B$3:$B$3<>""),MEDIDAS_Y_PESO!$B$3:$B$3),"--") -> 80 | U21: =IFERROR(IF(IF(X21>0,X21,IF(Z21>0,Z21,IF(AB21>0,AB21,0)))=0,"--",ROUND(CHOOSE(IF(X21>0,X21,IF(Z21>0,Z21,IF(AB21>0,AB21,0))),IF(C21="peso_corporal",IF(ISNUMBER(E21),E21,0)+F21,F21)*(1+G21/30),IF(C21="peso_corporal",IF(ISNUMBER(E21),E21,0)+I21,I21)*(1+J21/30),IF(C21="peso_corporal",IF(ISNUMBER(E21),E21,0)+L21,L21)*(1+M21/30),IF(C21="peso_corporal",IF(ISNUMBER(E21),E21,0)+O21,O21)*(1+P21/30),IF(C21="peso_corporal",IF(ISNUMBER(E21),E21,0)+R21,R21)*(1+S21/30)),1)),"--") -> -- | V21: =IF(SUGERENCIAS!N9="SIN","Sin datos anteriores",IF(SUGERENCIAS!N9="SUBIR_F","^ SUBIR FUERTE | Kg:"&ROUND(SUGERENCIAS!K9,1)&" R:"&ROUND(SUGERENCIAS!L9,0)&" RIR:"&ROUND(SUGERENCIAS!M9,0),IF(SUGERENCIAS!N9="SUBIR_E","^ SUBIR (Est.) | Kg:"&ROUND(SUGERENCIAS!K9,1)&" R:"&ROUND(SUGERENCIAS!L9,0)&" RIR:"&ROUND(SUGERENCIAS!M9,0),IF(SUGERENCIAS!N9="SUBIR","^ SUBIR | Kg:"&ROUND(SUGERENCIAS!K9,1)&" R:"&ROUND(SUGERENCIAS!L9,0)&" RIR:"&ROUND(SUGERENCIAS!M9,0),IF(SUGERENCIAS!N9="BAJAR","v BAJAR | Kg:"&ROUND(SUGERENCIAS!K9,1)&" R:"&ROUND(SUGERENCIAS!L9,0)&" RIR:"&ROUND(SUGERENCIAS!M9,0),"= MANT | Kg:"&ROUND(SUGERENCIAS!K9,1)&" R:"&ROUND(SUGERENCIAS!L9,0)&" RIR:"&ROUND(SUGERENCIAS!M9,0)))))) -> Sin datos anteriores | W21: =MAX(IF((G21>0)*(IF(H21="",-1,H21)>=1)*(IF(H21="",-1,H21)<=3),IF(C21="peso_corporal",IF(ISNUMBER(E21),E21,0)+F21,F21)*G21*1000+F21,0),IF((J21>0)*(IF(K21="",-1,K21)>=1)*(IF(K21="",-1,K21)<=3),IF(C21="peso_corporal",IF(ISNUMBER(E21),E21,0)+I21,I21)*J21*1000+I21,0),IF((M21>0)*(IF(N21="",-1,N21)>=1)*(IF(N21="",-1,N21)<=3),IF(C21="peso_corporal",IF(ISNUMBER(E21),E21,0)+L21,L21)*M21*1000+L21,0),IF((P21>0)*(IF(Q21="",-1,Q21)>=1)*(IF(Q21="",-1,Q21)<=3),IF(C21="peso_corporal",IF(ISNUMBER(E21),E21,0)+O21,O21)*P21*1000+O21,0),IF((S21>0)*(IF(T21="",-1,T21)>=1)*(IF(T21="",-1,T21)<=3),IF(C21="peso_corporal",IF(ISNUMBER(E21),E21,0)+R21,R21)*S21*1000+R21,0)) -> 0 | X21: =IF(W21=0,0,IF(IF((S21>0)*(IF(T21="",-1,T21)>=1)*(IF(T21="",-1,T21)<=3),IF(C21="peso_corporal",IF(ISNUMBER(E21),E21,0)+R21,R21)*S21*1000+R21,0)=W21,5,IF(IF((P21>0)*(IF(Q21="",-1,Q21)>=1)*(IF(Q21="",-1,Q21)<=3),IF(C21="peso_corporal",IF(ISNUMBER(E21),E21,0)+O21,O21)*P21*1000+O21,0)=W21,4,IF(IF((M21>0)*(IF(N21="",-1,N21)>=1)*(IF(N21="",-1,N21)<=3),IF(C21="peso_corporal",IF(ISNUMBER(E21),E21,0)+L21,L21)*M21*1000+L21,0)=W21,3,IF(IF((J21>0)*(IF(K21="",-1,K21)>=1)*(IF(K21="",-1,K21)<=3),IF(C21="peso_corporal",IF(ISNUMBER(E21),E21,0)+I21,I21)*J21*1000+I21,0)=W21,2,IF(IF((G21>0)*(IF(H21="",-1,H21)>=1)*(IF(H21="",-1,H21)<=3),IF(C21="peso_corporal",IF(ISNUMBER(E21),E21,0)+F21,F21)*G21*1000+F21,0)=W21,1,0)))))) -> 0 | Y21: =MAX(IF((G21>0)*(IF(H21="",-1,H21)=0)*(1-(IF(H21="",-1,H21)>=1)*(IF(H21="",-1,H21)<=3)),IF(C21="peso_corporal",IF(ISNUMBER(E21),E21,0)+F21,F21)*G21*1000+F21,0),IF((J21>0)*(IF(K21="",-1,K21)=0)*(1-(IF(K21="",-1,K21)>=1)*(IF(K21="",-1,K21)<=3)),IF(C21="peso_corporal",IF(ISNUMBER(E21),E21,0)+I21,I21)*J21*1000+I21,0),IF((M21>0)*(IF(N21="",-1,N21)=0)*(1-(IF(N21="",-1,N21)>=1)*(IF(N21="",-1,N21)<=3)),IF(C21="peso_corporal",IF(ISNUMBER(E21),E21,0)+L21,L21)*M21*1000+L21,0),IF((P21>0)*(IF(Q21="",-1,Q21)=0)*(1-(IF(Q21="",-1,Q21)>=1)*(IF(Q21="",-1,Q21)<=3)),IF(C21="peso_corporal",IF(ISNUMBER(E21),E21,0)+O21,O21)*P21*1000+O21,0),IF((S21>0)*(IF(T21="",-1,T21)=0)*(1-(IF(T21="",-1,T21)>=1)*(IF(T21="",-1,T21)<=3)),IF(C21="peso_corporal",IF(ISNUMBER(E21),E21,0)+R21,R21)*S21*1000+R21,0)) -> 0 | Z21: =IF(Y21=0,0,IF(IF((S21>0)*(IF(T21="",-1,T21)=0)*(1-(IF(T21="",-1,T21)>=1)*(IF(T21="",-1,T21)<=3)),IF(C21="peso_corporal",IF(ISNUMBER(E21),E21,0)+R21,R21)*S21*1000+R21,0)=Y21,5,IF(IF((P21>0)*(IF(Q21="",-1,Q21)=0)*(1-(IF(Q21="",-1,Q21)>=1)*(IF(Q21="",-1,Q21)<=3)),IF(C21="peso_corporal",IF(ISNUMBER(E21),E21,0)+O21,O21)*P21*1000+O21,0)=Y21,4,IF(IF((M21>0)*(IF(N21="",-1,N21)=0)*(1-(IF(N21="",-1,N21)>=1)*(IF(N21="",-1,N21)<=3)),IF(C21="peso_corporal",IF(ISNUMBER(E21),E21,0)+L21,L21)*M21*1000+L21,0)=Y21,3,IF(IF((J21>0)*(IF(K21="",-1,K21)=0)*(1-(IF(K21="",-1,K21)>=1)*(IF(K21="",-1,K21)<=3)),IF(C21="peso_corporal",IF(ISNUMBER(E21),E21,0)+I21,I21)*J21*1000+I21,0)=Y21,2,IF(IF((G21>0)*(IF(H21="",-1,H21)=0)*(1-(IF(H21="",-1,H21)>=1)*(IF(H21="",-1,H21)<=3)),IF(C21="peso_corporal",IF(ISNUMBER(E21),E21,0)+F21,F21)*G21*1000+F21,0)=Y21,1,0)))))) -> 0 | AA21: =MAX(IF((G21>=6)*(1-(IF(H21="",-1,H21)>=1)*(IF(H21="",-1,H21)<=3))*(1-(IF(H21="",-1,H21)=0)),IF(C21="peso_corporal",IF(ISNUMBER(E21),E21,0)+F21,F21)*(30+G21)*100+F21,0),IF((J21>=6)*(1-(IF(K21="",-1,K21)>=1)*(IF(K21="",-1,K21)<=3))*(1-(IF(K21="",-1,K21)=0)),IF(C21="peso_corporal",IF(ISNUMBER(E21),E21,0)+I21,I21)*(30+J21)*100+I21,0),IF((M21>=6)*(1-(IF(N21="",-1,N21)>=1)*(IF(N21="",-1,N21)<=3))*(1-(IF(N21="",-1,N21)=0)),IF(C21="peso_corporal",IF(ISNUMBER(E21),E21,0)+L21,L21)*(30+M21)*100+L21,0),IF((P21>=6)*(1-(IF(Q21="",-1,Q21)>=1)*(IF(Q21="",-1,Q21)<=3))*(1-(IF(Q21="",-1,Q21)=0)),IF(C21="peso_corporal",IF(ISNUMBER(E21),E21,0)+O21,O21)*(30+P21)*100+O21,0),IF((S21>=6)*(1-(IF(T21="",-1,T21)>=1)*(IF(T21="",-1,T21)<=3))*(1-(IF(T21="",-1,T21)=0)),IF(C21="peso_corporal",IF(ISNUMBER(E21),E21,0)+R21,R21)*(30+S21)*100+R21,0)) -> 0 | AB21: =IF(AA21=0,0,IF(IF((S21>=6)*(1-(IF(T21="",-1,T21)>=1)*(IF(T21="",-1,T21)<=3))*(1-(IF(T21="",-1,T21)=0)),IF(C21="peso_corporal",IF(ISNUMBER(E21),E21,0)+R21,R21)*(30+S21)*100+R21,0)=AA21,5,IF(IF((P21>=6)*(1-(IF(Q21="",-1,Q21)>=1)*(IF(Q21="",-1,Q21)<=3))*(1-(IF(Q21="",-1,Q21)=0)),IF(C21="peso_corporal",IF(ISNUMBER(E21),E21,0)+O21,O21)*(30+P21)*100+O21,0)=AA21,4,IF(IF((M21>=6)*(1-(IF(N21="",-1,N21)>=1)*(IF(N21="",-1,N21)<=3))*(1-(IF(N21="",-1,N21)=0)),IF(C21="peso_corporal",IF(ISNUMBER(E21),E21,0)+L21,L21)*(30+M21)*100+L21,0)=AA21,3,IF(IF((J21>=6)*(1-(IF(K21="",-1,K21)>=1)*(IF(K21="",-1,K21)<=3))*(1-(IF(K21="",-1,K21)=0)),IF(C21="peso_corporal",IF(ISNUMBER(E21),E21,0)+I21,I21)*(30+J21)*100+I21,0)=AA21,2,IF(IF((G21>=6)*(1-(IF(H21="",-1,H21)>=1)*(IF(H21="",-1,H21)<=3))*(1-(IF(H21="",-1,H21)=0)),IF(C21="peso_corporal",IF(ISNUMBER(E21),E21,0)+F21,F21)*(30+G21)*100+F21,0)=AA21,1,0)))))) -> 0 | AC21: =IF(X21>0,"A"&X21,IF(Z21>0,"B"&Z21,IF(AB21>0,"C"&AB21,"")))
A22: Press Militar | B22: Mancuernas Sentado | C22: =IFERROR(INDEX(EJERCICIOS!$D$3:$D$75,MATCH(A22&"|"&B22,EJERCICIOS!$G$3:$G$75,0)),"--") -> mancuerna | D22: 3 | E22: =IFERROR(LOOKUP(2,1/(MEDIDAS_Y_PESO!$B$3:$B$3<>""),MEDIDAS_Y_PESO!$B$3:$B$3),"--") -> 80 | U22: =IFERROR(IF(IF(X22>0,X22,IF(Z22>0,Z22,IF(AB22>0,AB22,0)))=0,"--",ROUND(CHOOSE(IF(X22>0,X22,IF(Z22>0,Z22,IF(AB22>0,AB22,0))),IF(C22="peso_corporal",IF(ISNUMBER(E22),E22,0)+F22,F22)*(1+G22/30),IF(C22="peso_corporal",IF(ISNUMBER(E22),E22,0)+I22,I22)*(1+J22/30),IF(C22="peso_corporal",IF(ISNUMBER(E22),E22,0)+L22,L22)*(1+M22/30),IF(C22="peso_corporal",IF(ISNUMBER(E22),E22,0)+O22,O22)*(1+P22/30),IF(C22="peso_corporal",IF(ISNUMBER(E22),E22,0)+R22,R22)*(1+S22/30)),1)),"--") -> -- | V22: =IF(SUGERENCIAS!N10="SIN","Sin datos anteriores",IF(SUGERENCIAS!N10="SUBIR_F","^ SUBIR FUERTE | Kg:"&ROUND(SUGERENCIAS!K10,1)&" R:"&ROUND(SUGERENCIAS!L10,0)&" RIR:"&ROUND(SUGERENCIAS!M10,0),IF(SUGERENCIAS!N10="SUBIR_E","^ SUBIR (Est.) | Kg:"&ROUND(SUGERENCIAS!K10,1)&" R:"&ROUND(SUGERENCIAS!L10,0)&" RIR:"&ROUND(SUGERENCIAS!M10,0),IF(SUGERENCIAS!N10="SUBIR","^ SUBIR | Kg:"&ROUND(SUGERENCIAS!K10,1)&" R:"&ROUND(SUGERENCIAS!L10,0)&" RIR:"&ROUND(SUGERENCIAS!M10,0),IF(SUGERENCIAS!N10="BAJAR","v BAJAR | Kg:"&ROUND(SUGERENCIAS!K10,1)&" R:"&ROUND(SUGERENCIAS!L10,0)&" RIR:"&ROUND(SUGERENCIAS!M10,0),"= MANT | Kg:"&ROUND(SUGERENCIAS!K10,1)&" R:"&ROUND(SUGERENCIAS!L10,0)&" RIR:"&ROUND(SUGERENCIAS!M10,0)))))) -> Sin datos anteriores | W22: =MAX(IF((G22>0)*(IF(H22="",-1,H22)>=1)*(IF(H22="",-1,H22)<=3),IF(C22="peso_corporal",IF(ISNUMBER(E22),E22,0)+F22,F22)*G22*1000+F22,0),IF((J22>0)*(IF(K22="",-1,K22)>=1)*(IF(K22="",-1,K22)<=3),IF(C22="peso_corporal",IF(ISNUMBER(E22),E22,0)+I22,I22)*J22*1000+I22,0),IF((M22>0)*(IF(N22="",-1,N22)>=1)*(IF(N22="",-1,N22)<=3),IF(C22="peso_corporal",IF(ISNUMBER(E22),E22,0)+L22,L22)*M22*1000+L22,0),IF((P22>0)*(IF(Q22="",-1,Q22)>=1)*(IF(Q22="",-1,Q22)<=3),IF(C22="peso_corporal",IF(ISNUMBER(E22),E22,0)+O22,O22)*P22*1000+O22,0),IF((S22>0)*(IF(T22="",-1,T22)>=1)*(IF(T22="",-1,T22)<=3),IF(C22="peso_corporal",IF(ISNUMBER(E22),E22,0)+R22,R22)*S22*1000+R22,0)) -> 0 | X22: =IF(W22=0,0,IF(IF((S22>0)*(IF(T22="",-1,T22)>=1)*(IF(T22="",-1,T22)<=3),IF(C22="peso_corporal",IF(ISNUMBER(E22),E22,0)+R22,R22)*S22*1000+R22,0)=W22,5,IF(IF((P22>0)*(IF(Q22="",-1,Q22)>=1)*(IF(Q22="",-1,Q22)<=3),IF(C22="peso_corporal",IF(ISNUMBER(E22),E22,0)+O22,O22)*P22*1000+O22,0)=W22,4,IF(IF((M22>0)*(IF(N22="",-1,N22)>=1)*(IF(N22="",-1,N22)<=3),IF(C22="peso_corporal",IF(ISNUMBER(E22),E22,0)+L22,L22)*M22*1000+L22,0)=W22,3,IF(IF((J22>0)*(IF(K22="",-1,K22)>=1)*(IF(K22="",-1,K22)<=3),IF(C22="peso_corporal",IF(ISNUMBER(E22),E22,0)+I22,I22)*J22*1000+I22,0)=W22,2,IF(IF((G22>0)*(IF(H22="",-1,H22)>=1)*(IF(H22="",-1,H22)<=3),IF(C22="peso_corporal",IF(ISNUMBER(E22),E22,0)+F22,F22)*G22*1000+F22,0)=W22,1,0)))))) -> 0 | Y22: =MAX(IF((G22>0)*(IF(H22="",-1,H22)=0)*(1-(IF(H22="",-1,H22)>=1)*(IF(H22="",-1,H22)<=3)),IF(C22="peso_corporal",IF(ISNUMBER(E22),E22,0)+F22,F22)*G22*1000+F22,0),IF((J22>0)*(IF(K22="",-1,K22)=0)*(1-(IF(K22="",-1,K22)>=1)*(IF(K22="",-1,K22)<=3)),IF(C22="peso_corporal",IF(ISNUMBER(E22),E22,0)+I22,I22)*J22*1000+I22,0),IF((M22>0)*(IF(N22="",-1,N22)=0)*(1-(IF(N22="",-1,N22)>=1)*(IF(N22="",-1,N22)<=3)),IF(C22="peso_corporal",IF(ISNUMBER(E22),E22,0)+L22,L22)*M22*1000+L22,0),IF((P22>0)*(IF(Q22="",-1,Q22)=0)*(1-(IF(Q22="",-1,Q22)>=1)*(IF(Q22="",-1,Q22)<=3)),IF(C22="peso_corporal",IF(ISNUMBER(E22),E22,0)+O22,O22)*P22*1000+O22,0),IF((S22>0)*(IF(T22="",-1,T22)=0)*(1-(IF(T22="",-1,T22)>=1)*(IF(T22="",-1,T22)<=3)),IF(C22="peso_corporal",IF(ISNUMBER(E22),E22,0)+R22,R22)*S22*1000+R22,0)) -> 0 | Z22: =IF(Y22=0,0,IF(IF((S22>0)*(IF(T22="",-1,T22)=0)*(1-(IF(T22="",-1,T22)>=1)*(IF(T22="",-1,T22)<=3)),IF(C22="peso_corporal",IF(ISNUMBER(E22),E22,0)+R22,R22)*S22*1000+R22,0)=Y22,5,IF(IF((P22>0)*(IF(Q22="",-1,Q22)=0)*(1-(IF(Q22="",-1,Q22)>=1)*(IF(Q22="",-1,Q22)<=3)),IF(C22="peso_corporal",IF(ISNUMBER(E22),E22,0)+O22,O22)*P22*1000+O22,0)=Y22,4,IF(IF((M22>0)*(IF(N22="",-1,N22)=0)*(1-(IF(N22="",-1,N22)>=1)*(IF(N22="",-1,N22)<=3)),IF(C22="peso_corporal",IF(ISNUMBER(E22),E22,0)+L22,L22)*M22*1000+L22,0)=Y22,3,IF(IF((J22>0)*(IF(K22="",-1,K22)=0)*(1-(IF(K22="",-1,K22)>=1)*(IF(K22="",-1,K22)<=3)),IF(C22="peso_corporal",IF(ISNUMBER(E22),E22,0)+I22,I22)*J22*1000+I22,0)=Y22,2,IF(IF((G22>0)*(IF(H22="",-1,H22)=0)*(1-(IF(H22="",-1,H22)>=1)*(IF(H22="",-1,H22)<=3)),IF(C22="peso_corporal",IF(ISNUMBER(E22),E22,0)+F22,F22)*G22*1000+F22,0)=Y22,1,0)))))) -> 0 | AA22: =MAX(IF((G22>=6)*(1-(IF(H22="",-1,H22)>=1)*(IF(H22="",-1,H22)<=3))*(1-(IF(H22="",-1,H22)=0)),IF(C22="peso_corporal",IF(ISNUMBER(E22),E22,0)+F22,F22)*(30+G22)*100+F22,0),IF((J22>=6)*(1-(IF(K22="",-1,K22)>=1)*(IF(K22="",-1,K22)<=3))*(1-(IF(K22="",-1,K22)=0)),IF(C22="peso_corporal",IF(ISNUMBER(E22),E22,0)+I22,I22)*(30+J22)*100+I22,0),IF((M22>=6)*(1-(IF(N22="",-1,N22)>=1)*(IF(N22="",-1,N22)<=3))*(1-(IF(N22="",-1,N22)=0)),IF(C22="peso_corporal",IF(ISNUMBER(E22),E22,0)+L22,L22)*(30+M22)*100+L22,0),IF((P22>=6)*(1-(IF(Q22="",-1,Q22)>=1)*(IF(Q22="",-1,Q22)<=3))*(1-(IF(Q22="",-1,Q22)=0)),IF(C22="peso_corporal",IF(ISNUMBER(E22),E22,0)+O22,O22)*(30+P22)*100+O22,0),IF((S22>=6)*(1-(IF(T22="",-1,T22)>=1)*(IF(T22="",-1,T22)<=3))*(1-(IF(T22="",-1,T22)=0)),IF(C22="peso_corporal",IF(ISNUMBER(E22),E22,0)+R22,R22)*(30+S22)*100+R22,0)) -> 0 | AB22: =IF(AA22=0,0,IF(IF((S22>=6)*(1-(IF(T22="",-1,T22)>=1)*(IF(T22="",-1,T22)<=3))*(1-(IF(T22="",-1,T22)=0)),IF(C22="peso_corporal",IF(ISNUMBER(E22),E22,0)+R22,R22)*(30+S22)*100+R22,0)=AA22,5,IF(IF((P22>=6)*(1-(IF(Q22="",-1,Q22)>=1)*(IF(Q22="",-1,Q22)<=3))*(1-(IF(Q22="",-1,Q22)=0)),IF(C22="peso_corporal",IF(ISNUMBER(E22),E22,0)+O22,O22)*(30+P22)*100+O22,0)=AA22,4,IF(IF((M22>=6)*(1-(IF(N22="",-1,N22)>=1)*(IF(N22="",-1,N22)<=3))*(1-(IF(N22="",-1,N22)=0)),IF(C22="peso_corporal",IF(ISNUMBER(E22),E22,0)+L22,L22)*(30+M22)*100+L22,0)=AA22,3,IF(IF((J22>=6)*(1-(IF(K22="",-1,K22)>=1)*(IF(K22="",-1,K22)<=3))*(1-(IF(K22="",-1,K22)=0)),IF(C22="peso_corporal",IF(ISNUMBER(E22),E22,0)+I22,I22)*(30+J22)*100+I22,0)=AA22,2,IF(IF((G22>=6)*(1-(IF(H22="",-1,H22)>=1)*(IF(H22="",-1,H22)<=3))*(1-(IF(H22="",-1,H22)=0)),IF(C22="peso_corporal",IF(ISNUMBER(E22),E22,0)+F22,F22)*(30+G22)*100+F22,0)=AA22,1,0)))))) -> 0 | AC22: =IF(X22>0,"A"&X22,IF(Z22>0,"B"&Z22,IF(AB22>0,"C"&AB22,"")))
A23: — TRICEPS —
A24: Extension Triceps | B24: Katana | C24: =IFERROR(INDEX(EJERCICIOS!$D$3:$D$75,MATCH(A24&"|"&B24,EJERCICIOS!$G$3:$G$75,0)),"--") -> polea | D24: 3 | E24: =IFERROR(LOOKUP(2,1/(MEDIDAS_Y_PESO!$B$3:$B$3<>""),MEDIDAS_Y_PESO!$B$3:$B$3),"--") -> 80 | U24: =IFERROR(IF(IF(X24>0,X24,IF(Z24>0,Z24,IF(AB24>0,AB24,0)))=0,"--",ROUND(CHOOSE(IF(X24>0,X24,IF(Z24>0,Z24,IF(AB24>0,AB24,0))),IF(C24="peso_corporal",IF(ISNUMBER(E24),E24,0)+F24,F24)*(1+G24/30),IF(C24="peso_corporal",IF(ISNUMBER(E24),E24,0)+I24,I24)*(1+J24/30),IF(C24="peso_corporal",IF(ISNUMBER(E24),E24,0)+L24,L24)*(1+M24/30),IF(C24="peso_corporal",IF(ISNUMBER(E24),E24,0)+O24,O24)*(1+P24/30),IF(C24="peso_corporal",IF(ISNUMBER(E24),E24,0)+R24,R24)*(1+S24/30)),1)),"--") -> -- | V24: =IF(SUGERENCIAS!N11="SIN","Sin datos anteriores",IF(SUGERENCIAS!N11="SUBIR_F","^ SUBIR FUERTE | Kg:"&ROUND(SUGERENCIAS!K11,1)&" R:"&ROUND(SUGERENCIAS!L11,0)&" RIR:"&ROUND(SUGERENCIAS!M11,0),IF(SUGERENCIAS!N11="SUBIR_E","^ SUBIR (Est.) | Kg:"&ROUND(SUGERENCIAS!K11,1)&" R:"&ROUND(SUGERENCIAS!L11,0)&" RIR:"&ROUND(SUGERENCIAS!M11,0),IF(SUGERENCIAS!N11="SUBIR","^ SUBIR | Kg:"&ROUND(SUGERENCIAS!K11,1)&" R:"&ROUND(SUGERENCIAS!L11,0)&" RIR:"&ROUND(SUGERENCIAS!M11,0),IF(SUGERENCIAS!N11="BAJAR","v BAJAR | Kg:"&ROUND(SUGERENCIAS!K11,1)&" R:"&ROUND(SUGERENCIAS!L11,0)&" RIR:"&ROUND(SUGERENCIAS!M11,0),"= MANT | Kg:"&ROUND(SUGERENCIAS!K11,1)&" R:"&ROUND(SUGERENCIAS!L11,0)&" RIR:"&ROUND(SUGERENCIAS!M11,0)))))) -> Sin datos anteriores | W24: =MAX(IF((G24>0)*(IF(H24="",-1,H24)>=1)*(IF(H24="",-1,H24)<=3),IF(C24="peso_corporal",IF(ISNUMBER(E24),E24,0)+F24,F24)*G24*1000+F24,0),IF((J24>0)*(IF(K24="",-1,K24)>=1)*(IF(K24="",-1,K24)<=3),IF(C24="peso_corporal",IF(ISNUMBER(E24),E24,0)+I24,I24)*J24*1000+I24,0),IF((M24>0)*(IF(N24="",-1,N24)>=1)*(IF(N24="",-1,N24)<=3),IF(C24="peso_corporal",IF(ISNUMBER(E24),E24,0)+L24,L24)*M24*1000+L24,0),IF((P24>0)*(IF(Q24="",-1,Q24)>=1)*(IF(Q24="",-1,Q24)<=3),IF(C24="peso_corporal",IF(ISNUMBER(E24),E24,0)+O24,O24)*P24*1000+O24,0),IF((S24>0)*(IF(T24="",-1,T24)>=1)*(IF(T24="",-1,T24)<=3),IF(C24="peso_corporal",IF(ISNUMBER(E24),E24,0)+R24,R24)*S24*1000+R24,0)) -> 0 | X24: =IF(W24=0,0,IF(IF((S24>0)*(IF(T24="",-1,T24)>=1)*(IF(T24="",-1,T24)<=3),IF(C24="peso_corporal",IF(ISNUMBER(E24),E24,0)+R24,R24)*S24*1000+R24,0)=W24,5,IF(IF((P24>0)*(IF(Q24="",-1,Q24)>=1)*(IF(Q24="",-1,Q24)<=3),IF(C24="peso_corporal",IF(ISNUMBER(E24),E24,0)+O24,O24)*P24*1000+O24,0)=W24,4,IF(IF((M24>0)*(IF(N24="",-1,N24)>=1)*(IF(N24="",-1,N24)<=3),IF(C24="peso_corporal",IF(ISNUMBER(E24),E24,0)+L24,L24)*M24*1000+L24,0)=W24,3,IF(IF((J24>0)*(IF(K24="",-1,K24)>=1)*(IF(K24="",-1,K24)<=3),IF(C24="peso_corporal",IF(ISNUMBER(E24),E24,0)+I24,I24)*J24*1000+I24,0)=W24,2,IF(IF((G24>0)*(IF(H24="",-1,H24)>=1)*(IF(H24="",-1,H24)<=3),IF(C24="peso_corporal",IF(ISNUMBER(E24),E24,0)+F24,F24)*G24*1000+F24,0)=W24,1,0)))))) -> 0 | Y24: =MAX(IF((G24>0)*(IF(H24="",-1,H24)=0)*(1-(IF(H24="",-1,H24)>=1)*(IF(H24="",-1,H24)<=3)),IF(C24="peso_corporal",IF(ISNUMBER(E24),E24,0)+F24,F24)*G24*1000+F24,0),IF((J24>0)*(IF(K24="",-1,K24)=0)*(1-(IF(K24="",-1,K24)>=1)*(IF(K24="",-1,K24)<=3)),IF(C24="peso_corporal",IF(ISNUMBER(E24),E24,0)+I24,I24)*J24*1000+I24,0),IF((M24>0)*(IF(N24="",-1,N24)=0)*(1-(IF(N24="",-1,N24)>=1)*(IF(N24="",-1,N24)<=3)),IF(C24="peso_corporal",IF(ISNUMBER(E24),E24,0)+L24,L24)*M24*1000+L24,0),IF((P24>0)*(IF(Q24="",-1,Q24)=0)*(1-(IF(Q24="",-1,Q24)>=1)*(IF(Q24="",-1,Q24)<=3)),IF(C24="peso_corporal",IF(ISNUMBER(E24),E24,0)+O24,O24)*P24*1000+O24,0),IF((S24>0)*(IF(T24="",-1,T24)=0)*(1-(IF(T24="",-1,T24)>=1)*(IF(T24="",-1,T24)<=3)),IF(C24="peso_corporal",IF(ISNUMBER(E24),E24,0)+R24,R24)*S24*1000+R24,0)) -> 0 | Z24: =IF(Y24=0,0,IF(IF((S24>0)*(IF(T24="",-1,T24)=0)*(1-(IF(T24="",-1,T24)>=1)*(IF(T24="",-1,T24)<=3)),IF(C24="peso_corporal",IF(ISNUMBER(E24),E24,0)+R24,R24)*S24*1000+R24,0)=Y24,5,IF(IF((P24>0)*(IF(Q24="",-1,Q24)=0)*(1-(IF(Q24="",-1,Q24)>=1)*(IF(Q24="",-1,Q24)<=3)),IF(C24="peso_corporal",IF(ISNUMBER(E24),E24,0)+O24,O24)*P24*1000+O24,0)=Y24,4,IF(IF((M24>0)*(IF(N24="",-1,N24)=0)*(1-(IF(N24="",-1,N24)>=1)*(IF(N24="",-1,N24)<=3)),IF(C24="peso_corporal",IF(ISNUMBER(E24),E24,0)+L24,L24)*M24*1000+L24,0)=Y24,3,IF(IF((J24>0)*(IF(K24="",-1,K24)=0)*(1-(IF(K24="",-1,K24)>=1)*(IF(K24="",-1,K24)<=3)),IF(C24="peso_corporal",IF(ISNUMBER(E24),E24,0)+I24,I24)*J24*1000+I24,0)=Y24,2,IF(IF((G24>0)*(IF(H24="",-1,H24)=0)*(1-(IF(H24="",-1,H24)>=1)*(IF(H24="",-1,H24)<=3)),IF(C24="peso_corporal",IF(ISNUMBER(E24),E24,0)+F24,F24)*G24*1000+F24,0)=Y24,1,0)))))) -> 0 | AA24: =MAX(IF((G24>=6)*(1-(IF(H24="",-1,H24)>=1)*(IF(H24="",-1,H24)<=3))*(1-(IF(H24="",-1,H24)=0)),IF(C24="peso_corporal",IF(ISNUMBER(E24),E24,0)+F24,F24)*(30+G24)*100+F24,0),IF((J24>=6)*(1-(IF(K24="",-1,K24)>=1)*(IF(K24="",-1,K24)<=3))*(1-(IF(K24="",-1,K24)=0)),IF(C24="peso_corporal",IF(ISNUMBER(E24),E24,0)+I24,I24)*(30+J24)*100+I24,0),IF((M24>=6)*(1-(IF(N24="",-1,N24)>=1)*(IF(N24="",-1,N24)<=3))*(1-(IF(N24="",-1,N24)=0)),IF(C24="peso_corporal",IF(ISNUMBER(E24),E24,0)+L24,L24)*(30+M24)*100+L24,0),IF((P24>=6)*(1-(IF(Q24="",-1,Q24)>=1)*(IF(Q24="",-1,Q24)<=3))*(1-(IF(Q24="",-1,Q24)=0)),IF(C24="peso_corporal",IF(ISNUMBER(E24),E24,0)+O24,O24)*(30+P24)*100+O24,0),IF((S24>=6)*(1-(IF(T24="",-1,T24)>=1)*(IF(T24="",-1,T24)<=3))*(1-(IF(T24="",-1,T24)=0)),IF(C24="peso_corporal",IF(ISNUMBER(E24),E24,0)+R24,R24)*(30+S24)*100+R24,0)) -> 0 | AB24: =IF(AA24=0,0,IF(IF((S24>=6)*(1-(IF(T24="",-1,T24)>=1)*(IF(T24="",-1,T24)<=3))*(1-(IF(T24="",-1,T24)=0)),IF(C24="peso_corporal",IF(ISNUMBER(E24),E24,0)+R24,R24)*(30+S24)*100+R24,0)=AA24,5,IF(IF((P24>=6)*(1-(IF(Q24="",-1,Q24)>=1)*(IF(Q24="",-1,Q24)<=3))*(1-(IF(Q24="",-1,Q24)=0)),IF(C24="peso_corporal",IF(ISNUMBER(E24),E24,0)+O24,O24)*(30+P24)*100+O24,0)=AA24,4,IF(IF((M24>=6)*(1-(IF(N24="",-1,N24)>=1)*(IF(N24="",-1,N24)<=3))*(1-(IF(N24="",-1,N24)=0)),IF(C24="peso_corporal",IF(ISNUMBER(E24),E24,0)+L24,L24)*(30+M24)*100+L24,0)=AA24,3,IF(IF((J24>=6)*(1-(IF(K24="",-1,K24)>=1)*(IF(K24="",-1,K24)<=3))*(1-(IF(K24="",-1,K24)=0)),IF(C24="peso_corporal",IF(ISNUMBER(E24),E24,0)+I24,I24)*(30+J24)*100+I24,0)=AA24,2,IF(IF((G24>=6)*(1-(IF(H24="",-1,H24)>=1)*(IF(H24="",-1,H24)<=3))*(1-(IF(H24="",-1,H24)=0)),IF(C24="peso_corporal",IF(ISNUMBER(E24),E24,0)+F24,F24)*(30+G24)*100+F24,0)=AA24,1,0)))))) -> 0 | AC24: =IF(X24>0,"A"&X24,IF(Z24>0,"B"&Z24,IF(AB24>0,"C"&AB24,"")))
A25: — CUADRICEPS —
